[2021-11-22 11:44:37,374] {taskinstance.py:1035} INFO - Dependencies all met for <TaskInstance: ELT-python-snowflake.Extract manual__2021-11-22T11:44:35.720896+00:00 [queued]>
[2021-11-22 11:44:37,394] {taskinstance.py:1035} INFO - Dependencies all met for <TaskInstance: ELT-python-snowflake.Extract manual__2021-11-22T11:44:35.720896+00:00 [queued]>
[2021-11-22 11:44:37,396] {taskinstance.py:1241} INFO - 
--------------------------------------------------------------------------------
[2021-11-22 11:44:37,396] {taskinstance.py:1242} INFO - Starting attempt 1 of 1
[2021-11-22 11:44:37,397] {taskinstance.py:1243} INFO - 
--------------------------------------------------------------------------------
[2021-11-22 11:44:37,414] {taskinstance.py:1262} INFO - Executing <Task(BashOperator): Extract> on 2021-11-22 11:44:35.720896+00:00
[2021-11-22 11:44:37,424] {standard_task_runner.py:52} INFO - Started process 919 to run task
[2021-11-22 11:44:37,429] {standard_task_runner.py:76} INFO - Running: ['***', 'tasks', 'run', 'ELT-python-snowflake', 'Extract', 'manual__2021-11-22T11:44:35.720896+00:00', '--job-id', '5', '--raw', '--subdir', 'DAGS_FOLDER/ELT-python-snowflake.py', '--cfg-path', '/tmp/tmpw424gpd6', '--error-file', '/tmp/tmpgwg94k_o']
[2021-11-22 11:44:37,430] {standard_task_runner.py:77} INFO - Job 5: Subtask Extract
[2021-11-22 11:44:37,481] {logging_mixin.py:109} INFO - Running <TaskInstance: ELT-python-snowflake.Extract manual__2021-11-22T11:44:35.720896+00:00 [running]> on host 0241c731c31b
[2021-11-22 11:44:37,541] {taskinstance.py:1429} INFO - Exporting the following env vars:
AIRFLOW_CTX_DAG_OWNER=***
AIRFLOW_CTX_DAG_ID=ELT-python-snowflake
AIRFLOW_CTX_TASK_ID=Extract
AIRFLOW_CTX_EXECUTION_DATE=2021-11-22T11:44:35.720896+00:00
AIRFLOW_CTX_DAG_RUN_ID=manual__2021-11-22T11:44:35.720896+00:00
[2021-11-22 11:44:37,542] {subprocess.py:62} INFO - Tmp dir root location: 
 /tmp
[2021-11-22 11:44:37,544] {subprocess.py:74} INFO - Running command: ['bash', '-c', 'python3 /opt/***/elt/user-orders/extract-load/mysql_to_s3.py']
[2021-11-22 11:44:37,562] {subprocess.py:85} INFO - Output:
[2021-11-22 11:44:40,846] {subprocess.py:89} INFO - JAVA_HOME is not set
[2021-11-22 11:44:40,912] {subprocess.py:89} INFO - /home/***/.local/lib/python3.7/site-packages/snowflake/connector/options.py:97: UserWarning: You have an incompatible version of 'pyarrow' installed (4.0.1), please install a version that adheres to: 'pyarrow<5.1.0,>=5.0.0; extra == "pandas"'
[2021-11-22 11:44:40,914] {subprocess.py:89} INFO -   _expected_pyarrow_version,
[2021-11-22 11:44:40,917] {subprocess.py:89} INFO - Traceback (most recent call last):
[2021-11-22 11:44:40,918] {subprocess.py:89} INFO -   File "/opt/***/elt/user-orders/extract-load/mysql_to_s3.py", line 38, in <module>
[2021-11-22 11:44:40,918] {subprocess.py:89} INFO -     context = SparkContext(master="local[*]", appName="readJSON")
[2021-11-22 11:44:40,919] {subprocess.py:89} INFO -   File "/home/***/.local/lib/python3.7/site-packages/pyspark/context.py", line 144, in __init__
[2021-11-22 11:44:40,920] {subprocess.py:89} INFO -     SparkContext._ensure_initialized(self, gateway=gateway, conf=conf)
[2021-11-22 11:44:40,921] {subprocess.py:89} INFO -   File "/home/***/.local/lib/python3.7/site-packages/pyspark/context.py", line 331, in _ensure_initialized
[2021-11-22 11:44:40,921] {subprocess.py:89} INFO -     SparkContext._gateway = gateway or launch_gateway(conf)
[2021-11-22 11:44:40,922] {subprocess.py:89} INFO -   File "/home/***/.local/lib/python3.7/site-packages/pyspark/java_gateway.py", line 108, in launch_gateway
[2021-11-22 11:44:40,923] {subprocess.py:89} INFO -     raise Exception("Java gateway process exited before sending its port number")
[2021-11-22 11:44:40,923] {subprocess.py:89} INFO - Exception: Java gateway process exited before sending its port number
[2021-11-22 11:44:41,120] {subprocess.py:93} INFO - Command exited with return code 1
[2021-11-22 11:44:41,140] {taskinstance.py:1703} ERROR - Task failed with exception
Traceback (most recent call last):
  File "/home/airflow/.local/lib/python3.7/site-packages/airflow/models/taskinstance.py", line 1332, in _run_raw_task
    self._execute_task_with_callbacks(context)
  File "/home/airflow/.local/lib/python3.7/site-packages/airflow/models/taskinstance.py", line 1458, in _execute_task_with_callbacks
    result = self._execute_task(context, self.task)
  File "/home/airflow/.local/lib/python3.7/site-packages/airflow/models/taskinstance.py", line 1514, in _execute_task
    result = execute_callable(context=context)
  File "/home/airflow/.local/lib/python3.7/site-packages/airflow/operators/bash.py", line 188, in execute
    f'Bash command failed. The command returned a non-zero exit code {result.exit_code}.'
airflow.exceptions.AirflowException: Bash command failed. The command returned a non-zero exit code 1.
[2021-11-22 11:44:41,162] {taskinstance.py:1280} INFO - Marking task as FAILED. dag_id=ELT-python-snowflake, task_id=Extract, execution_date=20211122T114435, start_date=20211122T114437, end_date=20211122T114441
[2021-11-22 11:44:41,192] {standard_task_runner.py:91} ERROR - Failed to execute job 5 for task Extract
Traceback (most recent call last):
  File "/home/airflow/.local/lib/python3.7/site-packages/airflow/task/task_runner/standard_task_runner.py", line 85, in _start_by_fork
    args.func(args, dag=self.dag)
  File "/home/airflow/.local/lib/python3.7/site-packages/airflow/cli/cli_parser.py", line 48, in command
    return func(*args, **kwargs)
  File "/home/airflow/.local/lib/python3.7/site-packages/airflow/utils/cli.py", line 92, in wrapper
    return f(*args, **kwargs)
  File "/home/airflow/.local/lib/python3.7/site-packages/airflow/cli/commands/task_command.py", line 292, in task_run
    _run_task_by_selected_method(args, dag, ti)
  File "/home/airflow/.local/lib/python3.7/site-packages/airflow/cli/commands/task_command.py", line 107, in _run_task_by_selected_method
    _run_raw_task(args, ti)
  File "/home/airflow/.local/lib/python3.7/site-packages/airflow/cli/commands/task_command.py", line 184, in _run_raw_task
    error_file=args.error_file,
  File "/home/airflow/.local/lib/python3.7/site-packages/airflow/utils/session.py", line 70, in wrapper
    return func(*args, session=session, **kwargs)
  File "/home/airflow/.local/lib/python3.7/site-packages/airflow/models/taskinstance.py", line 1332, in _run_raw_task
    self._execute_task_with_callbacks(context)
  File "/home/airflow/.local/lib/python3.7/site-packages/airflow/models/taskinstance.py", line 1458, in _execute_task_with_callbacks
    result = self._execute_task(context, self.task)
  File "/home/airflow/.local/lib/python3.7/site-packages/airflow/models/taskinstance.py", line 1514, in _execute_task
    result = execute_callable(context=context)
  File "/home/airflow/.local/lib/python3.7/site-packages/airflow/operators/bash.py", line 188, in execute
    f'Bash command failed. The command returned a non-zero exit code {result.exit_code}.'
airflow.exceptions.AirflowException: Bash command failed. The command returned a non-zero exit code 1.
[2021-11-22 11:44:41,240] {local_task_job.py:154} INFO - Task exited with return code 1
[2021-11-22 11:44:41,296] {local_task_job.py:264} INFO - 0 downstream tasks scheduled from follow-on schedule check
