[2021-11-22 11:29:19,035] {processor.py:163} INFO - Started process (PID=590) to work on /opt/airflow/dags/elt-user-orders.py
[2021-11-22 11:29:19,037] {processor.py:625} INFO - Processing file /opt/airflow/dags/elt-user-orders.py for tasks to queue
[2021-11-22 11:29:19,039] {logging_mixin.py:109} INFO - [2021-11-22 11:29:19,039] {dagbag.py:500} INFO - Filling up the DagBag from /opt/airflow/dags/elt-user-orders.py
[2021-11-22 11:29:19,066] {logging_mixin.py:109} INFO - [2021-11-22 11:29:19,062] {dagbag.py:334} ERROR - Failed to import: /opt/airflow/dags/elt-user-orders.py
Traceback (most recent call last):
  File "/home/airflow/.local/lib/python3.7/site-packages/airflow/models/dagbag.py", line 331, in _load_modules_from_file
    loader.exec_module(new_module)
  File "<frozen importlib._bootstrap_external>", line 728, in exec_module
  File "<frozen importlib._bootstrap>", line 219, in _call_with_frames_removed
  File "/opt/airflow/dags/elt-user-orders.py", line 15, in <module>
    this_will_skip >> run_this_last
NameError: name 'this_will_skip' is not defined
[2021-11-22 11:29:19,084] {processor.py:639} WARNING - No viable dags retrieved from /opt/airflow/dags/elt-user-orders.py
[2021-11-22 11:29:19,093] {processor.py:171} INFO - Processing /opt/airflow/dags/elt-user-orders.py took 0.062 seconds
[2021-11-22 11:29:49,270] {processor.py:163} INFO - Started process (PID=653) to work on /opt/airflow/dags/elt-user-orders.py
[2021-11-22 11:29:49,279] {processor.py:625} INFO - Processing file /opt/airflow/dags/elt-user-orders.py for tasks to queue
[2021-11-22 11:29:49,282] {logging_mixin.py:109} INFO - [2021-11-22 11:29:49,282] {dagbag.py:500} INFO - Filling up the DagBag from /opt/airflow/dags/elt-user-orders.py
[2021-11-22 11:29:49,308] {logging_mixin.py:109} INFO - [2021-11-22 11:29:49,304] {dagbag.py:334} ERROR - Failed to import: /opt/airflow/dags/elt-user-orders.py
Traceback (most recent call last):
  File "/home/airflow/.local/lib/python3.7/site-packages/airflow/models/dagbag.py", line 331, in _load_modules_from_file
    loader.exec_module(new_module)
  File "<frozen importlib._bootstrap_external>", line 728, in exec_module
  File "<frozen importlib._bootstrap>", line 219, in _call_with_frames_removed
  File "/opt/airflow/dags/elt-user-orders.py", line 15, in <module>
    this_will_skip >> run_this_last
NameError: name 'this_will_skip' is not defined
[2021-11-22 11:29:49,340] {processor.py:639} WARNING - No viable dags retrieved from /opt/airflow/dags/elt-user-orders.py
[2021-11-22 11:29:49,350] {processor.py:171} INFO - Processing /opt/airflow/dags/elt-user-orders.py took 0.089 seconds
[2021-11-22 11:29:59,900] {processor.py:163} INFO - Started process (PID=660) to work on /opt/airflow/dags/elt-user-orders.py
[2021-11-22 11:29:59,906] {processor.py:625} INFO - Processing file /opt/airflow/dags/elt-user-orders.py for tasks to queue
[2021-11-22 11:29:59,909] {logging_mixin.py:109} INFO - [2021-11-22 11:29:59,909] {dagbag.py:500} INFO - Filling up the DagBag from /opt/airflow/dags/elt-user-orders.py
[2021-11-22 11:29:59,973] {logging_mixin.py:109} INFO - [2021-11-22 11:29:59,965] {dagbag.py:334} ERROR - Failed to import: /opt/airflow/dags/elt-user-orders.py
Traceback (most recent call last):
  File "/home/airflow/.local/lib/python3.7/site-packages/airflow/models/dagbag.py", line 331, in _load_modules_from_file
    loader.exec_module(new_module)
  File "<frozen importlib._bootstrap_external>", line 728, in exec_module
  File "<frozen importlib._bootstrap>", line 219, in _call_with_frames_removed
  File "/opt/airflow/dags/elt-user-orders.py", line 21, in <module>
    bash_command='echo 1',
  File "/home/airflow/.local/lib/python3.7/site-packages/airflow/models/baseoperator.py", line 188, in apply_defaults
    result = func(self, *args, **kwargs)
  File "/home/airflow/.local/lib/python3.7/site-packages/airflow/operators/bash.py", line 143, in __init__
    super().__init__(**kwargs)
  File "/home/airflow/.local/lib/python3.7/site-packages/airflow/models/baseoperator.py", line 188, in apply_defaults
    result = func(self, *args, **kwargs)
  File "/home/airflow/.local/lib/python3.7/site-packages/airflow/models/baseoperator.py", line 553, in __init__
    task_group.add(self)
  File "/home/airflow/.local/lib/python3.7/site-packages/airflow/utils/task_group.py", line 175, in add
    raise DuplicateTaskIdFound(f"Task id '{key}' has already been added to the DAG")
airflow.exceptions.DuplicateTaskIdFound: Task id 'stream_to_current' has already been added to the DAG
[2021-11-22 11:30:00,025] {processor.py:639} WARNING - No viable dags retrieved from /opt/airflow/dags/elt-user-orders.py
[2021-11-22 11:30:00,038] {processor.py:171} INFO - Processing /opt/airflow/dags/elt-user-orders.py took 0.148 seconds
[2021-11-22 11:30:23,227] {processor.py:163} INFO - Started process (PID=707) to work on /opt/airflow/dags/elt-user-orders.py
[2021-11-22 11:30:23,231] {processor.py:625} INFO - Processing file /opt/airflow/dags/elt-user-orders.py for tasks to queue
[2021-11-22 11:30:23,233] {logging_mixin.py:109} INFO - [2021-11-22 11:30:23,232] {dagbag.py:500} INFO - Filling up the DagBag from /opt/airflow/dags/elt-user-orders.py
[2021-11-22 11:30:23,260] {logging_mixin.py:109} INFO - [2021-11-22 11:30:23,257] {dagbag.py:334} ERROR - Failed to import: /opt/airflow/dags/elt-user-orders.py
Traceback (most recent call last):
  File "/home/airflow/.local/lib/python3.7/site-packages/airflow/models/dagbag.py", line 331, in _load_modules_from_file
    loader.exec_module(new_module)
  File "<frozen importlib._bootstrap_external>", line 728, in exec_module
  File "<frozen importlib._bootstrap>", line 219, in _call_with_frames_removed
  File "/opt/airflow/dags/elt-user-orders.py", line 21, in <module>
    bash_command='echo 1',
  File "/home/airflow/.local/lib/python3.7/site-packages/airflow/models/baseoperator.py", line 188, in apply_defaults
    result = func(self, *args, **kwargs)
  File "/home/airflow/.local/lib/python3.7/site-packages/airflow/operators/bash.py", line 143, in __init__
    super().__init__(**kwargs)
  File "/home/airflow/.local/lib/python3.7/site-packages/airflow/models/baseoperator.py", line 188, in apply_defaults
    result = func(self, *args, **kwargs)
  File "/home/airflow/.local/lib/python3.7/site-packages/airflow/models/baseoperator.py", line 553, in __init__
    task_group.add(self)
  File "/home/airflow/.local/lib/python3.7/site-packages/airflow/utils/task_group.py", line 175, in add
    raise DuplicateTaskIdFound(f"Task id '{key}' has already been added to the DAG")
airflow.exceptions.DuplicateTaskIdFound: Task id 'stream_to_current' has already been added to the DAG
[2021-11-22 11:30:23,279] {processor.py:639} WARNING - No viable dags retrieved from /opt/airflow/dags/elt-user-orders.py
[2021-11-22 11:30:23,287] {processor.py:171} INFO - Processing /opt/airflow/dags/elt-user-orders.py took 0.064 seconds
[2021-11-22 11:30:53,725] {processor.py:163} INFO - Started process (PID=772) to work on /opt/airflow/dags/elt-user-orders.py
[2021-11-22 11:30:53,735] {processor.py:625} INFO - Processing file /opt/airflow/dags/elt-user-orders.py for tasks to queue
[2021-11-22 11:30:53,737] {logging_mixin.py:109} INFO - [2021-11-22 11:30:53,737] {dagbag.py:500} INFO - Filling up the DagBag from /opt/airflow/dags/elt-user-orders.py
[2021-11-22 11:30:53,770] {logging_mixin.py:109} INFO - [2021-11-22 11:30:53,762] {dagbag.py:334} ERROR - Failed to import: /opt/airflow/dags/elt-user-orders.py
Traceback (most recent call last):
  File "/home/airflow/.local/lib/python3.7/site-packages/airflow/models/dagbag.py", line 331, in _load_modules_from_file
    loader.exec_module(new_module)
  File "<frozen importlib._bootstrap_external>", line 728, in exec_module
  File "<frozen importlib._bootstrap>", line 219, in _call_with_frames_removed
  File "/opt/airflow/dags/elt-user-orders.py", line 21, in <module>
    bash_command='echo 1',
  File "/home/airflow/.local/lib/python3.7/site-packages/airflow/models/baseoperator.py", line 188, in apply_defaults
    result = func(self, *args, **kwargs)
  File "/home/airflow/.local/lib/python3.7/site-packages/airflow/operators/bash.py", line 143, in __init__
    super().__init__(**kwargs)
  File "/home/airflow/.local/lib/python3.7/site-packages/airflow/models/baseoperator.py", line 188, in apply_defaults
    result = func(self, *args, **kwargs)
  File "/home/airflow/.local/lib/python3.7/site-packages/airflow/models/baseoperator.py", line 553, in __init__
    task_group.add(self)
  File "/home/airflow/.local/lib/python3.7/site-packages/airflow/utils/task_group.py", line 175, in add
    raise DuplicateTaskIdFound(f"Task id '{key}' has already been added to the DAG")
airflow.exceptions.DuplicateTaskIdFound: Task id 'stream_to_current' has already been added to the DAG
[2021-11-22 11:30:53,799] {processor.py:639} WARNING - No viable dags retrieved from /opt/airflow/dags/elt-user-orders.py
[2021-11-22 11:30:53,816] {processor.py:171} INFO - Processing /opt/airflow/dags/elt-user-orders.py took 0.097 seconds
[2021-11-22 11:30:55,747] {processor.py:163} INFO - Started process (PID=773) to work on /opt/airflow/dags/elt-user-orders.py
[2021-11-22 11:30:55,749] {processor.py:625} INFO - Processing file /opt/airflow/dags/elt-user-orders.py for tasks to queue
[2021-11-22 11:30:55,752] {logging_mixin.py:109} INFO - [2021-11-22 11:30:55,751] {dagbag.py:500} INFO - Filling up the DagBag from /opt/airflow/dags/elt-user-orders.py
[2021-11-22 11:30:55,813] {logging_mixin.py:109} INFO - [2021-11-22 11:30:55,808] {dagbag.py:334} ERROR - Failed to import: /opt/airflow/dags/elt-user-orders.py
Traceback (most recent call last):
  File "/home/airflow/.local/lib/python3.7/site-packages/airflow/models/dagbag.py", line 331, in _load_modules_from_file
    loader.exec_module(new_module)
  File "<frozen importlib._bootstrap_external>", line 728, in exec_module
  File "<frozen importlib._bootstrap>", line 219, in _call_with_frames_removed
  File "/opt/airflow/dags/elt-user-orders.py", line 21, in <module>
    bash_command='echo 1',
  File "/home/airflow/.local/lib/python3.7/site-packages/airflow/models/baseoperator.py", line 188, in apply_defaults
    result = func(self, *args, **kwargs)
  File "/home/airflow/.local/lib/python3.7/site-packages/airflow/operators/bash.py", line 143, in __init__
    super().__init__(**kwargs)
  File "/home/airflow/.local/lib/python3.7/site-packages/airflow/models/baseoperator.py", line 188, in apply_defaults
    result = func(self, *args, **kwargs)
  File "/home/airflow/.local/lib/python3.7/site-packages/airflow/models/baseoperator.py", line 553, in __init__
    task_group.add(self)
  File "/home/airflow/.local/lib/python3.7/site-packages/airflow/utils/task_group.py", line 175, in add
    raise DuplicateTaskIdFound(f"Task id '{key}' has already been added to the DAG")
airflow.exceptions.DuplicateTaskIdFound: Task id 'stream_to_current' has already been added to the DAG
[2021-11-22 11:30:55,841] {processor.py:639} WARNING - No viable dags retrieved from /opt/airflow/dags/elt-user-orders.py
[2021-11-22 11:30:55,851] {processor.py:171} INFO - Processing /opt/airflow/dags/elt-user-orders.py took 0.109 seconds
[2021-11-22 11:31:01,529] {processor.py:163} INFO - Started process (PID=780) to work on /opt/airflow/dags/elt-user-orders.py
[2021-11-22 11:31:01,531] {processor.py:625} INFO - Processing file /opt/airflow/dags/elt-user-orders.py for tasks to queue
[2021-11-22 11:31:01,533] {logging_mixin.py:109} INFO - [2021-11-22 11:31:01,533] {dagbag.py:500} INFO - Filling up the DagBag from /opt/airflow/dags/elt-user-orders.py
[2021-11-22 11:31:01,567] {logging_mixin.py:109} INFO - [2021-11-22 11:31:01,564] {dagbag.py:334} ERROR - Failed to import: /opt/airflow/dags/elt-user-orders.py
Traceback (most recent call last):
  File "/home/airflow/.local/lib/python3.7/site-packages/airflow/models/dagbag.py", line 331, in _load_modules_from_file
    loader.exec_module(new_module)
  File "<frozen importlib._bootstrap_external>", line 728, in exec_module
  File "<frozen importlib._bootstrap>", line 219, in _call_with_frames_removed
  File "/opt/airflow/dags/elt-user-orders.py", line 25, in <module>
    this_will_skip >> run_this_last
NameError: name 'this_will_skip' is not defined
[2021-11-22 11:31:01,594] {processor.py:639} WARNING - No viable dags retrieved from /opt/airflow/dags/elt-user-orders.py
[2021-11-22 11:31:01,607] {processor.py:171} INFO - Processing /opt/airflow/dags/elt-user-orders.py took 0.084 seconds
[2021-11-22 11:31:32,132] {processor.py:163} INFO - Started process (PID=843) to work on /opt/airflow/dags/elt-user-orders.py
[2021-11-22 11:31:32,135] {processor.py:625} INFO - Processing file /opt/airflow/dags/elt-user-orders.py for tasks to queue
[2021-11-22 11:31:32,137] {logging_mixin.py:109} INFO - [2021-11-22 11:31:32,137] {dagbag.py:500} INFO - Filling up the DagBag from /opt/airflow/dags/elt-user-orders.py
[2021-11-22 11:31:32,155] {logging_mixin.py:109} INFO - [2021-11-22 11:31:32,153] {dagbag.py:334} ERROR - Failed to import: /opt/airflow/dags/elt-user-orders.py
Traceback (most recent call last):
  File "/home/airflow/.local/lib/python3.7/site-packages/airflow/models/dagbag.py", line 331, in _load_modules_from_file
    loader.exec_module(new_module)
  File "<frozen importlib._bootstrap_external>", line 728, in exec_module
  File "<frozen importlib._bootstrap>", line 219, in _call_with_frames_removed
  File "/opt/airflow/dags/elt-user-orders.py", line 25, in <module>
    this_will_skip >> run_this_last
NameError: name 'this_will_skip' is not defined
[2021-11-22 11:31:32,175] {processor.py:639} WARNING - No viable dags retrieved from /opt/airflow/dags/elt-user-orders.py
[2021-11-22 11:31:32,186] {processor.py:171} INFO - Processing /opt/airflow/dags/elt-user-orders.py took 0.062 seconds
[2021-11-22 11:31:34,152] {processor.py:163} INFO - Started process (PID=844) to work on /opt/airflow/dags/elt-user-orders.py
[2021-11-22 11:31:34,156] {processor.py:625} INFO - Processing file /opt/airflow/dags/elt-user-orders.py for tasks to queue
[2021-11-22 11:31:34,159] {logging_mixin.py:109} INFO - [2021-11-22 11:31:34,159] {dagbag.py:500} INFO - Filling up the DagBag from /opt/airflow/dags/elt-user-orders.py
[2021-11-22 11:31:34,192] {logging_mixin.py:109} INFO - [2021-11-22 11:31:34,189] {dagbag.py:334} ERROR - Failed to import: /opt/airflow/dags/elt-user-orders.py
Traceback (most recent call last):
  File "/home/airflow/.local/lib/python3.7/site-packages/airflow/models/dagbag.py", line 331, in _load_modules_from_file
    loader.exec_module(new_module)
  File "<frozen importlib._bootstrap_external>", line 728, in exec_module
  File "<frozen importlib._bootstrap>", line 219, in _call_with_frames_removed
  File "/opt/airflow/dags/elt-user-orders.py", line 30, in <module>
    this_will_skip >> run_this_last
NameError: name 'this_will_skip' is not defined
[2021-11-22 11:31:34,222] {processor.py:639} WARNING - No viable dags retrieved from /opt/airflow/dags/elt-user-orders.py
[2021-11-22 11:31:34,235] {processor.py:171} INFO - Processing /opt/airflow/dags/elt-user-orders.py took 0.087 seconds
[2021-11-22 11:32:04,547] {processor.py:163} INFO - Started process (PID=898) to work on /opt/airflow/dags/elt-user-orders.py
[2021-11-22 11:32:04,549] {processor.py:625} INFO - Processing file /opt/airflow/dags/elt-user-orders.py for tasks to queue
[2021-11-22 11:32:04,551] {logging_mixin.py:109} INFO - [2021-11-22 11:32:04,551] {dagbag.py:500} INFO - Filling up the DagBag from /opt/airflow/dags/elt-user-orders.py
[2021-11-22 11:32:04,571] {logging_mixin.py:109} INFO - [2021-11-22 11:32:04,569] {dagbag.py:334} ERROR - Failed to import: /opt/airflow/dags/elt-user-orders.py
Traceback (most recent call last):
  File "/home/airflow/.local/lib/python3.7/site-packages/airflow/models/dagbag.py", line 331, in _load_modules_from_file
    loader.exec_module(new_module)
  File "<frozen importlib._bootstrap_external>", line 728, in exec_module
  File "<frozen importlib._bootstrap>", line 219, in _call_with_frames_removed
  File "/opt/airflow/dags/elt-user-orders.py", line 30, in <module>
    this_will_skip >> run_this_last
NameError: name 'this_will_skip' is not defined
[2021-11-22 11:32:04,593] {processor.py:639} WARNING - No viable dags retrieved from /opt/airflow/dags/elt-user-orders.py
[2021-11-22 11:32:04,609] {processor.py:171} INFO - Processing /opt/airflow/dags/elt-user-orders.py took 0.067 seconds
[2021-11-22 11:32:07,165] {processor.py:163} INFO - Started process (PID=909) to work on /opt/airflow/dags/elt-user-orders.py
[2021-11-22 11:32:07,167] {processor.py:625} INFO - Processing file /opt/airflow/dags/elt-user-orders.py for tasks to queue
[2021-11-22 11:32:07,169] {logging_mixin.py:109} INFO - [2021-11-22 11:32:07,169] {dagbag.py:500} INFO - Filling up the DagBag from /opt/airflow/dags/elt-user-orders.py
[2021-11-22 11:32:07,201] {logging_mixin.py:109} INFO - [2021-11-22 11:32:07,196] {dagbag.py:334} ERROR - Failed to import: /opt/airflow/dags/elt-user-orders.py
Traceback (most recent call last):
  File "/home/airflow/.local/lib/python3.7/site-packages/airflow/models/dagbag.py", line 331, in _load_modules_from_file
    loader.exec_module(new_module)
  File "<frozen importlib._bootstrap_external>", line 728, in exec_module
  File "<frozen importlib._bootstrap>", line 219, in _call_with_frames_removed
  File "/opt/airflow/dags/elt-user-orders.py", line 31, in <module>
    bash_command='echo 1',
  File "/home/airflow/.local/lib/python3.7/site-packages/airflow/models/baseoperator.py", line 188, in apply_defaults
    result = func(self, *args, **kwargs)
  File "/home/airflow/.local/lib/python3.7/site-packages/airflow/operators/bash.py", line 143, in __init__
    super().__init__(**kwargs)
  File "/home/airflow/.local/lib/python3.7/site-packages/airflow/models/baseoperator.py", line 188, in apply_defaults
    result = func(self, *args, **kwargs)
  File "/home/airflow/.local/lib/python3.7/site-packages/airflow/models/baseoperator.py", line 553, in __init__
    task_group.add(self)
  File "/home/airflow/.local/lib/python3.7/site-packages/airflow/utils/task_group.py", line 175, in add
    raise DuplicateTaskIdFound(f"Task id '{key}' has already been added to the DAG")
airflow.exceptions.DuplicateTaskIdFound: Task id 'dedup_to_extractcast' has already been added to the DAG
[2021-11-22 11:32:07,224] {processor.py:639} WARNING - No viable dags retrieved from /opt/airflow/dags/elt-user-orders.py
[2021-11-22 11:32:07,235] {processor.py:171} INFO - Processing /opt/airflow/dags/elt-user-orders.py took 0.076 seconds
[2021-11-22 11:32:07,486] {processor.py:163} INFO - Started process (PID=911) to work on /opt/airflow/dags/elt-user-orders.py
[2021-11-22 11:32:07,490] {processor.py:625} INFO - Processing file /opt/airflow/dags/elt-user-orders.py for tasks to queue
[2021-11-22 11:32:07,491] {logging_mixin.py:109} INFO - [2021-11-22 11:32:07,491] {dagbag.py:500} INFO - Filling up the DagBag from /opt/airflow/dags/elt-user-orders.py
[2021-11-22 11:32:07,517] {logging_mixin.py:109} INFO - [2021-11-22 11:32:07,511] {dagbag.py:334} ERROR - Failed to import: /opt/airflow/dags/elt-user-orders.py
Traceback (most recent call last):
  File "/home/airflow/.local/lib/python3.7/site-packages/airflow/models/dagbag.py", line 331, in _load_modules_from_file
    loader.exec_module(new_module)
  File "<frozen importlib._bootstrap_external>", line 728, in exec_module
  File "<frozen importlib._bootstrap>", line 219, in _call_with_frames_removed
  File "/opt/airflow/dags/elt-user-orders.py", line 31, in <module>
    bash_command='echo 1',
  File "/home/airflow/.local/lib/python3.7/site-packages/airflow/models/baseoperator.py", line 188, in apply_defaults
    result = func(self, *args, **kwargs)
  File "/home/airflow/.local/lib/python3.7/site-packages/airflow/operators/bash.py", line 143, in __init__
    super().__init__(**kwargs)
  File "/home/airflow/.local/lib/python3.7/site-packages/airflow/models/baseoperator.py", line 188, in apply_defaults
    result = func(self, *args, **kwargs)
  File "/home/airflow/.local/lib/python3.7/site-packages/airflow/models/baseoperator.py", line 553, in __init__
    task_group.add(self)
  File "/home/airflow/.local/lib/python3.7/site-packages/airflow/utils/task_group.py", line 175, in add
    raise DuplicateTaskIdFound(f"Task id '{key}' has already been added to the DAG")
airflow.exceptions.DuplicateTaskIdFound: Task id 'dedup_to_extractcast' has already been added to the DAG
[2021-11-22 11:32:07,549] {processor.py:639} WARNING - No viable dags retrieved from /opt/airflow/dags/elt-user-orders.py
[2021-11-22 11:32:07,558] {processor.py:171} INFO - Processing /opt/airflow/dags/elt-user-orders.py took 0.078 seconds
[2021-11-22 11:32:08,513] {processor.py:163} INFO - Started process (PID=912) to work on /opt/airflow/dags/elt-user-orders.py
[2021-11-22 11:32:08,518] {processor.py:625} INFO - Processing file /opt/airflow/dags/elt-user-orders.py for tasks to queue
[2021-11-22 11:32:08,523] {logging_mixin.py:109} INFO - [2021-11-22 11:32:08,522] {dagbag.py:500} INFO - Filling up the DagBag from /opt/airflow/dags/elt-user-orders.py
[2021-11-22 11:32:08,556] {logging_mixin.py:109} INFO - [2021-11-22 11:32:08,552] {dagbag.py:334} ERROR - Failed to import: /opt/airflow/dags/elt-user-orders.py
Traceback (most recent call last):
  File "/home/airflow/.local/lib/python3.7/site-packages/airflow/models/dagbag.py", line 331, in _load_modules_from_file
    loader.exec_module(new_module)
  File "<frozen importlib._bootstrap_external>", line 728, in exec_module
  File "<frozen importlib._bootstrap>", line 219, in _call_with_frames_removed
  File "/opt/airflow/dags/elt-user-orders.py", line 31, in <module>
    bash_command='echo 1',
  File "/home/airflow/.local/lib/python3.7/site-packages/airflow/models/baseoperator.py", line 188, in apply_defaults
    result = func(self, *args, **kwargs)
  File "/home/airflow/.local/lib/python3.7/site-packages/airflow/operators/bash.py", line 143, in __init__
    super().__init__(**kwargs)
  File "/home/airflow/.local/lib/python3.7/site-packages/airflow/models/baseoperator.py", line 188, in apply_defaults
    result = func(self, *args, **kwargs)
  File "/home/airflow/.local/lib/python3.7/site-packages/airflow/models/baseoperator.py", line 553, in __init__
    task_group.add(self)
  File "/home/airflow/.local/lib/python3.7/site-packages/airflow/utils/task_group.py", line 175, in add
    raise DuplicateTaskIdFound(f"Task id '{key}' has already been added to the DAG")
airflow.exceptions.DuplicateTaskIdFound: Task id 'dedup_to_extractcast' has already been added to the DAG
[2021-11-22 11:32:08,599] {processor.py:639} WARNING - No viable dags retrieved from /opt/airflow/dags/elt-user-orders.py
[2021-11-22 11:32:08,614] {processor.py:171} INFO - Processing /opt/airflow/dags/elt-user-orders.py took 0.113 seconds
[2021-11-22 11:32:17,022] {processor.py:163} INFO - Started process (PID=939) to work on /opt/airflow/dags/elt-user-orders.py
[2021-11-22 11:32:17,024] {processor.py:625} INFO - Processing file /opt/airflow/dags/elt-user-orders.py for tasks to queue
[2021-11-22 11:32:17,025] {logging_mixin.py:109} INFO - [2021-11-22 11:32:17,025] {dagbag.py:500} INFO - Filling up the DagBag from /opt/airflow/dags/elt-user-orders.py
[2021-11-22 11:32:17,056] {logging_mixin.py:109} INFO - [2021-11-22 11:32:17,053] {dagbag.py:334} ERROR - Failed to import: /opt/airflow/dags/elt-user-orders.py
Traceback (most recent call last):
  File "/home/airflow/.local/lib/python3.7/site-packages/airflow/models/dagbag.py", line 331, in _load_modules_from_file
    loader.exec_module(new_module)
  File "<frozen importlib._bootstrap_external>", line 728, in exec_module
  File "<frozen importlib._bootstrap>", line 219, in _call_with_frames_removed
  File "/opt/airflow/dags/elt-user-orders.py", line 45, in <module>
    this_will_skip >> run_this_last
NameError: name 'this_will_skip' is not defined
[2021-11-22 11:32:17,086] {processor.py:639} WARNING - No viable dags retrieved from /opt/airflow/dags/elt-user-orders.py
[2021-11-22 11:32:17,098] {processor.py:171} INFO - Processing /opt/airflow/dags/elt-user-orders.py took 0.080 seconds
[2021-11-22 11:32:18,008] {processor.py:163} INFO - Started process (PID=940) to work on /opt/airflow/dags/elt-user-orders.py
[2021-11-22 11:32:18,010] {processor.py:625} INFO - Processing file /opt/airflow/dags/elt-user-orders.py for tasks to queue
[2021-11-22 11:32:18,011] {logging_mixin.py:109} INFO - [2021-11-22 11:32:18,011] {dagbag.py:500} INFO - Filling up the DagBag from /opt/airflow/dags/elt-user-orders.py
[2021-11-22 11:32:18,036] {logging_mixin.py:109} INFO - [2021-11-22 11:32:18,034] {dagbag.py:334} ERROR - Failed to import: /opt/airflow/dags/elt-user-orders.py
Traceback (most recent call last):
  File "/home/airflow/.local/lib/python3.7/site-packages/airflow/models/dagbag.py", line 331, in _load_modules_from_file
    loader.exec_module(new_module)
  File "<frozen importlib._bootstrap_external>", line 728, in exec_module
  File "<frozen importlib._bootstrap>", line 219, in _call_with_frames_removed
  File "/opt/airflow/dags/elt-user-orders.py", line 45, in <module>
    this_will_skip >> run_this_last
NameError: name 'this_will_skip' is not defined
[2021-11-22 11:32:18,055] {processor.py:639} WARNING - No viable dags retrieved from /opt/airflow/dags/elt-user-orders.py
[2021-11-22 11:32:18,064] {processor.py:171} INFO - Processing /opt/airflow/dags/elt-user-orders.py took 0.061 seconds
[2021-11-22 11:32:34,964] {processor.py:163} INFO - Started process (PID=957) to work on /opt/airflow/dags/elt-user-orders.py
[2021-11-22 11:32:34,966] {processor.py:625} INFO - Processing file /opt/airflow/dags/elt-user-orders.py for tasks to queue
[2021-11-22 11:32:34,968] {logging_mixin.py:109} INFO - [2021-11-22 11:32:34,967] {dagbag.py:500} INFO - Filling up the DagBag from /opt/airflow/dags/elt-user-orders.py
[2021-11-22 11:32:34,993] {logging_mixin.py:109} INFO - [2021-11-22 11:32:34,991] {dagbag.py:334} ERROR - Failed to import: /opt/airflow/dags/elt-user-orders.py
Traceback (most recent call last):
  File "/home/airflow/.local/lib/python3.7/site-packages/airflow/models/dagbag.py", line 331, in _load_modules_from_file
    loader.exec_module(new_module)
  File "<frozen importlib._bootstrap_external>", line 728, in exec_module
  File "<frozen importlib._bootstrap>", line 219, in _call_with_frames_removed
  File "/opt/airflow/dags/elt-user-orders.py", line 45, in <module>
    this_will_skip >> run_this_last
NameError: name 'this_will_skip' is not defined
[2021-11-22 11:32:35,017] {processor.py:639} WARNING - No viable dags retrieved from /opt/airflow/dags/elt-user-orders.py
[2021-11-22 11:32:35,028] {processor.py:171} INFO - Processing /opt/airflow/dags/elt-user-orders.py took 0.069 seconds
[2021-11-22 11:32:35,274] {processor.py:163} INFO - Started process (PID=959) to work on /opt/airflow/dags/elt-user-orders.py
[2021-11-22 11:32:35,277] {processor.py:625} INFO - Processing file /opt/airflow/dags/elt-user-orders.py for tasks to queue
[2021-11-22 11:32:35,279] {logging_mixin.py:109} INFO - [2021-11-22 11:32:35,279] {dagbag.py:500} INFO - Filling up the DagBag from /opt/airflow/dags/elt-user-orders.py
[2021-11-22 11:32:35,307] {logging_mixin.py:109} INFO - [2021-11-22 11:32:35,304] {dagbag.py:334} ERROR - Failed to import: /opt/airflow/dags/elt-user-orders.py
Traceback (most recent call last):
  File "/home/airflow/.local/lib/python3.7/site-packages/airflow/models/dagbag.py", line 331, in _load_modules_from_file
    loader.exec_module(new_module)
  File "<frozen importlib._bootstrap_external>", line 728, in exec_module
  File "<frozen importlib._bootstrap>", line 219, in _call_with_frames_removed
  File "/opt/airflow/dags/elt-user-orders.py", line 45, in <module>
    this_will_skip >> run_this_last
NameError: name 'this_will_skip' is not defined
[2021-11-22 11:32:35,327] {processor.py:639} WARNING - No viable dags retrieved from /opt/airflow/dags/elt-user-orders.py
[2021-11-22 11:32:35,335] {processor.py:171} INFO - Processing /opt/airflow/dags/elt-user-orders.py took 0.068 seconds
[2021-11-22 11:32:41,697] {processor.py:163} INFO - Started process (PID=984) to work on /opt/airflow/dags/elt-user-orders.py
[2021-11-22 11:32:41,699] {processor.py:625} INFO - Processing file /opt/airflow/dags/elt-user-orders.py for tasks to queue
[2021-11-22 11:32:41,701] {logging_mixin.py:109} INFO - [2021-11-22 11:32:41,701] {dagbag.py:500} INFO - Filling up the DagBag from /opt/airflow/dags/elt-user-orders.py
[2021-11-22 11:32:41,733] {logging_mixin.py:109} INFO - [2021-11-22 11:32:41,731] {dagbag.py:334} ERROR - Failed to import: /opt/airflow/dags/elt-user-orders.py
Traceback (most recent call last):
  File "/home/airflow/.local/lib/python3.7/site-packages/airflow/models/dagbag.py", line 331, in _load_modules_from_file
    loader.exec_module(new_module)
  File "<frozen importlib._bootstrap_external>", line 728, in exec_module
  File "<frozen importlib._bootstrap>", line 219, in _call_with_frames_removed
  File "/opt/airflow/dags/elt-user-orders.py", line 45, in <module>
    this_will_skip >> run_this_last
NameError: name 'this_will_skip' is not defined
[2021-11-22 11:32:41,756] {processor.py:639} WARNING - No viable dags retrieved from /opt/airflow/dags/elt-user-orders.py
[2021-11-22 11:32:41,767] {processor.py:171} INFO - Processing /opt/airflow/dags/elt-user-orders.py took 0.074 seconds
[2021-11-22 11:32:42,357] {processor.py:163} INFO - Started process (PID=990) to work on /opt/airflow/dags/elt-user-orders.py
[2021-11-22 11:32:42,360] {processor.py:625} INFO - Processing file /opt/airflow/dags/elt-user-orders.py for tasks to queue
[2021-11-22 11:32:42,362] {logging_mixin.py:109} INFO - [2021-11-22 11:32:42,361] {dagbag.py:500} INFO - Filling up the DagBag from /opt/airflow/dags/elt-user-orders.py
[2021-11-22 11:32:42,386] {logging_mixin.py:109} INFO - [2021-11-22 11:32:42,383] {dagbag.py:334} ERROR - Failed to import: /opt/airflow/dags/elt-user-orders.py
Traceback (most recent call last):
  File "/home/airflow/.local/lib/python3.7/site-packages/airflow/models/dagbag.py", line 331, in _load_modules_from_file
    loader.exec_module(new_module)
  File "<frozen importlib._bootstrap_external>", line 728, in exec_module
  File "<frozen importlib._bootstrap>", line 219, in _call_with_frames_removed
  File "/opt/airflow/dags/elt-user-orders.py", line 45, in <module>
    this_will_skip >> run_this_last
NameError: name 'this_will_skip' is not defined
[2021-11-22 11:32:42,411] {processor.py:639} WARNING - No viable dags retrieved from /opt/airflow/dags/elt-user-orders.py
[2021-11-22 11:32:42,424] {processor.py:171} INFO - Processing /opt/airflow/dags/elt-user-orders.py took 0.071 seconds
[2021-11-22 11:32:43,069] {processor.py:163} INFO - Started process (PID=997) to work on /opt/airflow/dags/elt-user-orders.py
[2021-11-22 11:32:43,072] {processor.py:625} INFO - Processing file /opt/airflow/dags/elt-user-orders.py for tasks to queue
[2021-11-22 11:32:43,074] {logging_mixin.py:109} INFO - [2021-11-22 11:32:43,073] {dagbag.py:500} INFO - Filling up the DagBag from /opt/airflow/dags/elt-user-orders.py
[2021-11-22 11:32:43,106] {logging_mixin.py:109} INFO - [2021-11-22 11:32:43,104] {dagbag.py:334} ERROR - Failed to import: /opt/airflow/dags/elt-user-orders.py
Traceback (most recent call last):
  File "/home/airflow/.local/lib/python3.7/site-packages/airflow/models/dagbag.py", line 331, in _load_modules_from_file
    loader.exec_module(new_module)
  File "<frozen importlib._bootstrap_external>", line 728, in exec_module
  File "<frozen importlib._bootstrap>", line 219, in _call_with_frames_removed
  File "/opt/airflow/dags/elt-user-orders.py", line 45, in <module>
    this_will_skip >> run_this_last
NameError: name 'this_will_skip' is not defined
[2021-11-22 11:32:43,133] {processor.py:639} WARNING - No viable dags retrieved from /opt/airflow/dags/elt-user-orders.py
[2021-11-22 11:32:43,148] {processor.py:171} INFO - Processing /opt/airflow/dags/elt-user-orders.py took 0.091 seconds
[2021-11-22 11:32:43,729] {processor.py:163} INFO - Started process (PID=999) to work on /opt/airflow/dags/elt-user-orders.py
[2021-11-22 11:32:43,732] {processor.py:625} INFO - Processing file /opt/airflow/dags/elt-user-orders.py for tasks to queue
[2021-11-22 11:32:43,735] {logging_mixin.py:109} INFO - [2021-11-22 11:32:43,735] {dagbag.py:500} INFO - Filling up the DagBag from /opt/airflow/dags/elt-user-orders.py
[2021-11-22 11:32:43,772] {logging_mixin.py:109} INFO - [2021-11-22 11:32:43,770] {dagbag.py:334} ERROR - Failed to import: /opt/airflow/dags/elt-user-orders.py
Traceback (most recent call last):
  File "/home/airflow/.local/lib/python3.7/site-packages/airflow/models/dagbag.py", line 331, in _load_modules_from_file
    loader.exec_module(new_module)
  File "<frozen importlib._bootstrap_external>", line 728, in exec_module
  File "<frozen importlib._bootstrap>", line 219, in _call_with_frames_removed
  File "/opt/airflow/dags/elt-user-orders.py", line 45, in <module>
    this_will_skip >> run_this_last
NameError: name 'this_will_skip' is not defined
[2021-11-22 11:32:43,804] {processor.py:639} WARNING - No viable dags retrieved from /opt/airflow/dags/elt-user-orders.py
[2021-11-22 11:32:43,819] {processor.py:171} INFO - Processing /opt/airflow/dags/elt-user-orders.py took 0.095 seconds
