[2021-11-22 12:13:55,814] {taskinstance.py:1035} INFO - Dependencies all met for <TaskInstance: ELT-python-snowflake.Extract manual__2021-11-22T12:13:54.092620+00:00 [queued]>
[2021-11-22 12:13:55,831] {taskinstance.py:1035} INFO - Dependencies all met for <TaskInstance: ELT-python-snowflake.Extract manual__2021-11-22T12:13:54.092620+00:00 [queued]>
[2021-11-22 12:13:55,832] {taskinstance.py:1241} INFO - 
--------------------------------------------------------------------------------
[2021-11-22 12:13:55,833] {taskinstance.py:1242} INFO - Starting attempt 1 of 1
[2021-11-22 12:13:55,834] {taskinstance.py:1243} INFO - 
--------------------------------------------------------------------------------
[2021-11-22 12:13:55,858] {taskinstance.py:1262} INFO - Executing <Task(BashOperator): Extract> on 2021-11-22 12:13:54.092620+00:00
[2021-11-22 12:13:55,866] {standard_task_runner.py:52} INFO - Started process 111 to run task
[2021-11-22 12:13:55,875] {standard_task_runner.py:76} INFO - Running: ['***', 'tasks', 'run', 'ELT-python-snowflake', 'Extract', 'manual__2021-11-22T12:13:54.092620+00:00', '--job-id', '12', '--raw', '--subdir', 'DAGS_FOLDER/ELT-python-snowflake.py', '--cfg-path', '/tmp/tmpr53yg79o', '--error-file', '/tmp/tmp8ybxf_2s']
[2021-11-22 12:13:55,877] {standard_task_runner.py:77} INFO - Job 12: Subtask Extract
[2021-11-22 12:13:55,976] {logging_mixin.py:109} INFO - Running <TaskInstance: ELT-python-snowflake.Extract manual__2021-11-22T12:13:54.092620+00:00 [running]> on host 2d962cb2f938
[2021-11-22 12:13:56,076] {taskinstance.py:1429} INFO - Exporting the following env vars:
AIRFLOW_CTX_DAG_OWNER=***
AIRFLOW_CTX_DAG_ID=ELT-python-snowflake
AIRFLOW_CTX_TASK_ID=Extract
AIRFLOW_CTX_EXECUTION_DATE=2021-11-22T12:13:54.092620+00:00
AIRFLOW_CTX_DAG_RUN_ID=manual__2021-11-22T12:13:54.092620+00:00
[2021-11-22 12:13:56,081] {subprocess.py:62} INFO - Tmp dir root location: 
 /tmp
[2021-11-22 12:13:56,085] {subprocess.py:74} INFO - Running command: ['bash', '-c', 'python3 /opt/***/elt/user-orders/extract-load/mysql_to_s3.py']
[2021-11-22 12:13:56,110] {subprocess.py:85} INFO - Output:
[2021-11-22 12:14:02,078] {subprocess.py:89} INFO - WARNING: An illegal reflective access operation has occurred
[2021-11-22 12:14:02,079] {subprocess.py:89} INFO - WARNING: Illegal reflective access by org.apache.spark.unsafe.Platform (file:/home/***/.local/lib/python3.7/site-packages/pyspark/jars/spark-unsafe_2.12-3.1.1.jar) to constructor java.nio.DirectByteBuffer(long,int)
[2021-11-22 12:14:02,080] {subprocess.py:89} INFO - WARNING: Please consider reporting this to the maintainers of org.apache.spark.unsafe.Platform
[2021-11-22 12:14:02,081] {subprocess.py:89} INFO - WARNING: Use --illegal-access=warn to enable warnings of further illegal reflective access operations
[2021-11-22 12:14:02,082] {subprocess.py:89} INFO - WARNING: All illegal access operations will be denied in a future release
[2021-11-22 12:14:02,876] {subprocess.py:89} INFO - 21/11/22 12:14:02 WARN NativeCodeLoader: Unable to load native-hadoop library for your platform... using builtin-java classes where applicable
[2021-11-22 12:14:03,368] {subprocess.py:89} INFO - Using Spark's default log4j profile: org/apache/spark/log4j-defaults.properties
[2021-11-22 12:14:03,371] {subprocess.py:89} INFO - Setting default log level to "WARN".
[2021-11-22 12:14:03,375] {subprocess.py:89} INFO - To adjust logging level use sc.setLogLevel(newLevel). For SparkR, use setLogLevel(newLevel).
[2021-11-22 12:14:09,375] {subprocess.py:89} INFO - /home/***/.local/lib/python3.7/site-packages/snowflake/connector/options.py:97: UserWarning: You have an incompatible version of 'pyarrow' installed (4.0.1), please install a version that adheres to: 'pyarrow<5.1.0,>=5.0.0; extra == "pandas"'
[2021-11-22 12:14:09,376] {subprocess.py:89} INFO -   _expected_pyarrow_version,
[2021-11-22 12:14:09,377] {subprocess.py:89} INFO - uploading entity: USERS
[2021-11-22 12:14:09,385] {subprocess.py:89} INFO - Traceback (most recent call last):
[2021-11-22 12:14:09,386] {subprocess.py:89} INFO -   File "/opt/***/elt/user-orders/extract-load/mysql_to_s3.py", line 83, in <module>
[2021-11-22 12:14:09,387] {subprocess.py:89} INFO -     .option("password", oltp_password)\
[2021-11-22 12:14:09,387] {subprocess.py:89} INFO -   File "/home/***/.local/lib/python3.7/site-packages/pyspark/sql/readwriter.py", line 210, in load
[2021-11-22 12:14:09,388] {subprocess.py:89} INFO -     return self._df(self._jreader.load())
[2021-11-22 12:14:09,389] {subprocess.py:89} INFO -   File "/home/***/.local/lib/python3.7/site-packages/py4j/java_gateway.py", line 1305, in __call__
[2021-11-22 12:14:09,389] {subprocess.py:89} INFO -     answer, self.gateway_client, self.target_id, self.name)
[2021-11-22 12:14:09,390] {subprocess.py:89} INFO -   File "/home/***/.local/lib/python3.7/site-packages/pyspark/sql/utils.py", line 111, in deco
[2021-11-22 12:14:09,390] {subprocess.py:89} INFO -     return f(*a, **kw)
[2021-11-22 12:14:09,391] {subprocess.py:89} INFO -   File "/home/***/.local/lib/python3.7/site-packages/py4j/protocol.py", line 328, in get_return_value
[2021-11-22 12:14:09,392] {subprocess.py:89} INFO -     format(target_id, ".", name), value)
[2021-11-22 12:14:09,392] {subprocess.py:89} INFO - py4j.protocol.Py4JJavaError: An error occurred while calling o40.load.
[2021-11-22 12:14:09,393] {subprocess.py:89} INFO - : com.mysql.cj.jdbc.exceptions.CommunicationsException: Communications link failure
[2021-11-22 12:14:09,394] {subprocess.py:89} INFO - 
[2021-11-22 12:14:09,395] {subprocess.py:89} INFO - The last packet sent successfully to the server was 0 milliseconds ago. The driver has not received any packets from the server.
[2021-11-22 12:14:09,395] {subprocess.py:89} INFO - 	at com.mysql.cj.jdbc.exceptions.SQLError.createCommunicationsException(SQLError.java:174)
[2021-11-22 12:14:09,396] {subprocess.py:89} INFO - 	at com.mysql.cj.jdbc.exceptions.SQLExceptionsMapping.translateException(SQLExceptionsMapping.java:64)
[2021-11-22 12:14:09,397] {subprocess.py:89} INFO - 	at com.mysql.cj.jdbc.ConnectionImpl.createNewIO(ConnectionImpl.java:832)
[2021-11-22 12:14:09,397] {subprocess.py:89} INFO - 	at com.mysql.cj.jdbc.ConnectionImpl.<init>(ConnectionImpl.java:456)
[2021-11-22 12:14:09,398] {subprocess.py:89} INFO - 	at com.mysql.cj.jdbc.ConnectionImpl.getInstance(ConnectionImpl.java:240)
[2021-11-22 12:14:09,398] {subprocess.py:89} INFO - 	at com.mysql.cj.jdbc.NonRegisteringDriver.connect(NonRegisteringDriver.java:207)
[2021-11-22 12:14:09,399] {subprocess.py:89} INFO - 	at org.apache.spark.sql.execution.datasources.jdbc.connection.BasicConnectionProvider.getConnection(BasicConnectionProvider.scala:49)
[2021-11-22 12:14:09,400] {subprocess.py:89} INFO - 	at org.apache.spark.sql.execution.datasources.jdbc.connection.ConnectionProvider$.create(ConnectionProvider.scala:63)
[2021-11-22 12:14:09,400] {subprocess.py:89} INFO - 	at org.apache.spark.sql.execution.datasources.jdbc.JdbcUtils$.$anonfun$createConnectionFactory$1(JdbcUtils.scala:62)
[2021-11-22 12:14:09,401] {subprocess.py:89} INFO - 	at org.apache.spark.sql.execution.datasources.jdbc.JDBCRDD$.resolveTable(JDBCRDD.scala:56)
[2021-11-22 12:14:09,402] {subprocess.py:89} INFO - 	at org.apache.spark.sql.execution.datasources.jdbc.JDBCRelation$.getSchema(JDBCRelation.scala:226)
[2021-11-22 12:14:09,402] {subprocess.py:89} INFO - 	at org.apache.spark.sql.execution.datasources.jdbc.JdbcRelationProvider.createRelation(JdbcRelationProvider.scala:35)
[2021-11-22 12:14:09,403] {subprocess.py:89} INFO - 	at org.apache.spark.sql.execution.datasources.DataSource.resolveRelation(DataSource.scala:354)
[2021-11-22 12:14:09,404] {subprocess.py:89} INFO - 	at org.apache.spark.sql.DataFrameReader.loadV1Source(DataFrameReader.scala:326)
[2021-11-22 12:14:09,404] {subprocess.py:89} INFO - 	at org.apache.spark.sql.DataFrameReader.$anonfun$load$3(DataFrameReader.scala:308)
[2021-11-22 12:14:09,405] {subprocess.py:89} INFO - 	at scala.Option.getOrElse(Option.scala:189)
[2021-11-22 12:14:09,406] {subprocess.py:89} INFO - 	at org.apache.spark.sql.DataFrameReader.load(DataFrameReader.scala:308)
[2021-11-22 12:14:09,407] {subprocess.py:89} INFO - 	at org.apache.spark.sql.DataFrameReader.load(DataFrameReader.scala:226)
[2021-11-22 12:14:09,408] {subprocess.py:89} INFO - 	at java.base/jdk.internal.reflect.NativeMethodAccessorImpl.invoke0(Native Method)
[2021-11-22 12:14:09,408] {subprocess.py:89} INFO - 	at java.base/jdk.internal.reflect.NativeMethodAccessorImpl.invoke(NativeMethodAccessorImpl.java:62)
[2021-11-22 12:14:09,409] {subprocess.py:89} INFO - 	at java.base/jdk.internal.reflect.DelegatingMethodAccessorImpl.invoke(DelegatingMethodAccessorImpl.java:43)
[2021-11-22 12:14:09,410] {subprocess.py:89} INFO - 	at java.base/java.lang.reflect.Method.invoke(Method.java:566)
[2021-11-22 12:14:09,410] {subprocess.py:89} INFO - 	at py4j.reflection.MethodInvoker.invoke(MethodInvoker.java:244)
[2021-11-22 12:14:09,411] {subprocess.py:89} INFO - 	at py4j.reflection.ReflectionEngine.invoke(ReflectionEngine.java:357)
[2021-11-22 12:14:09,412] {subprocess.py:89} INFO - 	at py4j.Gateway.invoke(Gateway.java:282)
[2021-11-22 12:14:09,412] {subprocess.py:89} INFO - 	at py4j.commands.AbstractCommand.invokeMethod(AbstractCommand.java:132)
[2021-11-22 12:14:09,413] {subprocess.py:89} INFO - 	at py4j.commands.CallCommand.execute(CallCommand.java:79)
[2021-11-22 12:14:09,414] {subprocess.py:89} INFO - 	at py4j.GatewayConnection.run(GatewayConnection.java:238)
[2021-11-22 12:14:09,415] {subprocess.py:89} INFO - 	at java.base/java.lang.Thread.run(Thread.java:829)
[2021-11-22 12:14:09,415] {subprocess.py:89} INFO - Caused by: com.mysql.cj.exceptions.CJCommunicationsException: Communications link failure
[2021-11-22 12:14:09,416] {subprocess.py:89} INFO - 
[2021-11-22 12:14:09,417] {subprocess.py:89} INFO - The last packet sent successfully to the server was 0 milliseconds ago. The driver has not received any packets from the server.
[2021-11-22 12:14:09,418] {subprocess.py:89} INFO - 	at java.base/jdk.internal.reflect.NativeConstructorAccessorImpl.newInstance0(Native Method)
[2021-11-22 12:14:09,418] {subprocess.py:89} INFO - 	at java.base/jdk.internal.reflect.NativeConstructorAccessorImpl.newInstance(NativeConstructorAccessorImpl.java:62)
[2021-11-22 12:14:09,419] {subprocess.py:89} INFO - 	at java.base/jdk.internal.reflect.DelegatingConstructorAccessorImpl.newInstance(DelegatingConstructorAccessorImpl.java:45)
[2021-11-22 12:14:09,420] {subprocess.py:89} INFO - 	at java.base/java.lang.reflect.Constructor.newInstance(Constructor.java:490)
[2021-11-22 12:14:09,420] {subprocess.py:89} INFO - 	at com.mysql.cj.exceptions.ExceptionFactory.createException(ExceptionFactory.java:61)
[2021-11-22 12:14:09,421] {subprocess.py:89} INFO - 	at com.mysql.cj.exceptions.ExceptionFactory.createException(ExceptionFactory.java:105)
[2021-11-22 12:14:09,422] {subprocess.py:89} INFO - 	at com.mysql.cj.exceptions.ExceptionFactory.createException(ExceptionFactory.java:151)
[2021-11-22 12:14:09,423] {subprocess.py:89} INFO - 	at com.mysql.cj.exceptions.ExceptionFactory.createCommunicationsException(ExceptionFactory.java:167)
[2021-11-22 12:14:09,423] {subprocess.py:89} INFO - 	at com.mysql.cj.protocol.a.NativeSocketConnection.connect(NativeSocketConnection.java:91)
[2021-11-22 12:14:09,424] {subprocess.py:89} INFO - 	at com.mysql.cj.NativeSession.connect(NativeSession.java:152)
[2021-11-22 12:14:09,425] {subprocess.py:89} INFO - 	at com.mysql.cj.jdbc.ConnectionImpl.connectOneTryOnly(ConnectionImpl.java:952)
[2021-11-22 12:14:09,425] {subprocess.py:89} INFO - 	at com.mysql.cj.jdbc.ConnectionImpl.createNewIO(ConnectionImpl.java:822)
[2021-11-22 12:14:09,426] {subprocess.py:89} INFO - 	... 26 more
[2021-11-22 12:14:09,427] {subprocess.py:89} INFO - Caused by: java.net.ConnectException: Connection refused (Connection refused)
[2021-11-22 12:14:09,428] {subprocess.py:89} INFO - 	at java.base/java.net.PlainSocketImpl.socketConnect(Native Method)
[2021-11-22 12:14:09,428] {subprocess.py:89} INFO - 	at java.base/java.net.AbstractPlainSocketImpl.doConnect(AbstractPlainSocketImpl.java:399)
[2021-11-22 12:14:09,429] {subprocess.py:89} INFO - 	at java.base/java.net.AbstractPlainSocketImpl.connectToAddress(AbstractPlainSocketImpl.java:242)
[2021-11-22 12:14:09,430] {subprocess.py:89} INFO - 	at java.base/java.net.AbstractPlainSocketImpl.connect(AbstractPlainSocketImpl.java:224)
[2021-11-22 12:14:09,431] {subprocess.py:89} INFO - 	at java.base/java.net.SocksSocketImpl.connect(SocksSocketImpl.java:392)
[2021-11-22 12:14:09,431] {subprocess.py:89} INFO - 	at java.base/java.net.Socket.connect(Socket.java:609)
[2021-11-22 12:14:09,432] {subprocess.py:89} INFO - 	at com.mysql.cj.protocol.StandardSocketFactory.connect(StandardSocketFactory.java:173)
[2021-11-22 12:14:09,432] {subprocess.py:89} INFO - 	at com.mysql.cj.protocol.a.NativeSocketConnection.connect(NativeSocketConnection.java:65)
[2021-11-22 12:14:09,433] {subprocess.py:89} INFO - 	... 29 more
[2021-11-22 12:14:09,433] {subprocess.py:89} INFO - 
[2021-11-22 12:14:10,226] {subprocess.py:93} INFO - Command exited with return code 1
[2021-11-22 12:14:10,246] {taskinstance.py:1703} ERROR - Task failed with exception
Traceback (most recent call last):
  File "/home/airflow/.local/lib/python3.7/site-packages/airflow/models/taskinstance.py", line 1332, in _run_raw_task
    self._execute_task_with_callbacks(context)
  File "/home/airflow/.local/lib/python3.7/site-packages/airflow/models/taskinstance.py", line 1458, in _execute_task_with_callbacks
    result = self._execute_task(context, self.task)
  File "/home/airflow/.local/lib/python3.7/site-packages/airflow/models/taskinstance.py", line 1514, in _execute_task
    result = execute_callable(context=context)
  File "/home/airflow/.local/lib/python3.7/site-packages/airflow/operators/bash.py", line 188, in execute
    f'Bash command failed. The command returned a non-zero exit code {result.exit_code}.'
airflow.exceptions.AirflowException: Bash command failed. The command returned a non-zero exit code 1.
[2021-11-22 12:14:10,259] {taskinstance.py:1280} INFO - Marking task as FAILED. dag_id=ELT-python-snowflake, task_id=Extract, execution_date=20211122T121354, start_date=20211122T121355, end_date=20211122T121410
[2021-11-22 12:14:10,285] {standard_task_runner.py:91} ERROR - Failed to execute job 12 for task Extract
Traceback (most recent call last):
  File "/home/airflow/.local/lib/python3.7/site-packages/airflow/task/task_runner/standard_task_runner.py", line 85, in _start_by_fork
    args.func(args, dag=self.dag)
  File "/home/airflow/.local/lib/python3.7/site-packages/airflow/cli/cli_parser.py", line 48, in command
    return func(*args, **kwargs)
  File "/home/airflow/.local/lib/python3.7/site-packages/airflow/utils/cli.py", line 92, in wrapper
    return f(*args, **kwargs)
  File "/home/airflow/.local/lib/python3.7/site-packages/airflow/cli/commands/task_command.py", line 292, in task_run
    _run_task_by_selected_method(args, dag, ti)
  File "/home/airflow/.local/lib/python3.7/site-packages/airflow/cli/commands/task_command.py", line 107, in _run_task_by_selected_method
    _run_raw_task(args, ti)
  File "/home/airflow/.local/lib/python3.7/site-packages/airflow/cli/commands/task_command.py", line 184, in _run_raw_task
    error_file=args.error_file,
  File "/home/airflow/.local/lib/python3.7/site-packages/airflow/utils/session.py", line 70, in wrapper
    return func(*args, session=session, **kwargs)
  File "/home/airflow/.local/lib/python3.7/site-packages/airflow/models/taskinstance.py", line 1332, in _run_raw_task
    self._execute_task_with_callbacks(context)
  File "/home/airflow/.local/lib/python3.7/site-packages/airflow/models/taskinstance.py", line 1458, in _execute_task_with_callbacks
    result = self._execute_task(context, self.task)
  File "/home/airflow/.local/lib/python3.7/site-packages/airflow/models/taskinstance.py", line 1514, in _execute_task
    result = execute_callable(context=context)
  File "/home/airflow/.local/lib/python3.7/site-packages/airflow/operators/bash.py", line 188, in execute
    f'Bash command failed. The command returned a non-zero exit code {result.exit_code}.'
airflow.exceptions.AirflowException: Bash command failed. The command returned a non-zero exit code 1.
[2021-11-22 12:14:10,330] {local_task_job.py:154} INFO - Task exited with return code 1
[2021-11-22 12:14:10,376] {local_task_job.py:264} INFO - 0 downstream tasks scheduled from follow-on schedule check
